Workbook
Name Dirección_Administrativa_Y_Financiera: f!$BD$84
Name Aprendiz: TBL_Aprendiz[Aprendiz]
Name Rol: TBL_Rol[Rol]
Name Sedes: TBL_Sedes[Ciudad Nombre de la sede]
Name Tipo_De_Contrato: Tabla2[Tipo De Contrato]
Name Tipo_De_Solicitud: TBL_Tipo_De_Solicitud[Tipo de solicitud]
Name Usuario_Externo: TBL_Usuario_Externo[Usuario Externo]
Name Aprendiz: TBL_Aprendiz[Aprendiz]
Name Area_Rural_A__7_Kms_De_La_Sede_Principal._Vereda_Aguadas: #REF!
Name Aseador_G01: #REF!
Name Aseador_G03: #REF!
Name Aseador_G04: #REF!
Name Aseador_G05: #REF!
Name Aseador_G06: #REF!
Name Aseador_G07: #REF!
Name Aseador_G08: #REF!
Name Aseador_G09: #REF!
Name Aseador_G10: #REF!
Name Asesor_G01: #REF!
Name Asesor_G02: #REF!
Name Asesor_G03: #REF!
Name Asesor_G04: #REF!
Name Asesor_G05: #REF!
Name Auxiliar_De_Cocina_G10: #REF!
Name Auxiliar_Enfermería_G10: #REF!
Name Auxiliar_G01: #REF!
Name Auxiliar_G02: #REF!
Name Av._5_Calle_18_An_Zona_Industrial: #REF!
Name Av._Circunvalar_Junto_Al_Colegio_Las_Cayenas_Kra._15_Sur___46__500: #REF!
Name Av_5_Calle_13_y_14__Granja_Las_Piedras: #REF!
Name Ave._1Ra_Calle_20_Esquina: #REF!
Name Avenida_10_No._29_–_06_Barrio_Patio_Centro: #REF!
Name Avenida_15_No._6___176_Barrio_San_José: #REF!
Name Avenida_15_No._6___176_Barrio_San_José46: #REF!
Name Avenida_15_No_5__62_Barrio_San_José._Mitú___Vaupés: #REF!
Name Avenida_30_No_17B_25_Sur: #REF!
Name Avenida_30_No_17B_25_Sur20: #REF!
Name Avenida_30_No_17B_25_Sur21: #REF!
Name Avenida_30_No_17B_25_Sur22: #REF!
Name Avenida_Canal_Bogotá___1N_30_Barrio_Pescadero___Cúcuta: #REF!
Name Avenida_Carracas_No_13_88: #REF!
Name Avenida_Centenario_42N_02: #REF!
Name Avenida_Circunvalar_Calle_24_Y_27: #REF!
Name Avenida_Circunvalar_Calle_24_Y_2718: #REF!
Name Avenida_Ferrocarril__27_97: #REF!
Name Avenida_Francisco_Newball: #REF!
Name Avenida_Francisco_Newball38: #REF!
Name Avenida_Paralela_Calle_55_Colegio_Inem_–_Bloque_C__Parte_De_Abajo.: #REF!
Name Avenida_Pedro_De_Heredia__Sector_Tesca: #REF!
Name Avenida_Providencia_1A___48_Edificio_Leda_Locales_201__202__203: #REF!
Name Avenida_Simón_Bolivar_Kilómetro_5: #REF!
Name Barrio_El_Senado.: #REF!
Name Barrio_La_Capilla___La_Unión_Nariño: #REF!
Name Barrio_Puerto_Espejo__Manzana___11: #REF!
Name Buenos_Aires: #REF!
Name Calle_1___1_130_Matevenado: #REF!
Name Calle_10___3_10: #REF!
Name Calle_10_No._1_21_Barrio_Chagualito: #REF!
Name Calle_11_Nº_11___109: #REF!
Name Calle_11_Nro._12_42: #REF!

Sheet Listas
A1: Tipo de solicitud | B1: Tipo De Contrato | C1: Contratista | D1: Planta | E1: Usuario Externo | F1: Rol | G1: vpn | H1: Aprendiz
A2: Activar | B2: Contratista | C2: Contratista | D2: Aseador G01 | E2: Usuario Externo | F2: Administrativo | G2: SI | H2: Contrato Aprendizaje SENA
A3: Crear | B3: Planta | D3: Aseador G03 | F3: Funcionario | G3: NO | H3: Etapa Productiva SENA
A4: Inactivar | B4: Usuario_Externo | D4: Aseador G04 | F4: Instructor
A5: Modificar | B5: Aprendiz | D5: Aseador G05 | F5: Director
D6: Aseador G06 | F6: Asesor
D7: Aseador G07 | F7: Subdirector
D8: Aseador G08 | F8: Jefe de Oficina
D9: Aseador G09 | F9: Coordinador
D10: Aseador G10 | F10: Profesional
D11: Asesor G01 | F11: Técnico
D12: Asesor G02 | F12: Secretaria
D13: Asesor G03 | F13: Asistencial
D14: Asesor G04 | F14: Auxiliar
D15: Asesor G05 | F15: Oficinista
D16: Auxiliar De Cocina G10 | F16: Trabajador Oficial
D17: Auxiliar Enfermería G10
D18: Auxiliar G01
D19: Auxiliar G02
D20: Conductor G07
D21: Conductor G08
D22: Conductor G09
D23: Conductor G10
D24: Director De Área G10
D25: Director General G11
D26: Director Regional A G08
D27: Director Regional B G07
D28: Director Regional C G04
... D88: Trabajador De Campo G10

Sheet SEDES
A1: Ciudad Nombre de la sede | B1: ID | C1: Código TIC | D1: Regional | E1: Ciudad | F1: Nombre de la sede | G1: Dirección | H1: Clase | I1: Tipo | J1: Horario Atención L-V | K1: Horario Sabatino | L1: Horario Dominical | M1: Estado | N1: Líder TIC | O1: Correo | P1: Celular | Q1: IP | R1: Sede Propia / Arriendo / Comodato | S1: Fecha inicio contrato | T1: Fecha fin contrato
A3: =_xlfn.CONCAT(TBL_Sedes[[#This Row],[Ciudad]]," ",TBL_Sedes[[#This Row],[Nombre de la sede]]) -> Aguachica Centro Agroempresarial | B3: 74 | C3: 95201000 | D3: Cesar | E3: Aguachica | F3: Centro Agroempresarial | G3: Km 1 Vía Bucaramanga | H3: Centro De Formación | I3: B | J3: 07:00 A 19:00 | K3: N/A | L3: N/A | M3: Activa | N3: Nataniel Romero Oñate | O3: nromeroo@sena.edu.co | P3: 3158722597 | Q3: 53280 | R3: Propia | S3: N/A | T3: N/A
A4: =_xlfn.CONCAT(TBL_Sedes[[#This Row],[Ciudad]]," ",TBL_Sedes[[#This Row],[Nombre de la sede]]) -> Apartadó Complejo Tecnológico Agroindustrial, Pecuario Y Turístico | B4: 18 | C4: 95041000 | D4: Antioquia | E4: Apartadó | F4: Complejo Tecnológico Agroindustrial, Pecuario Y Turístico | G4: Kilometro 1 Salida Turbo | H4: Centro De Formación | I4: A | J4: 07:00 A 20:00 | K4: 08:00 A 14:00 | L4: N/A | M4: Activa | N4: Ofelia Maria Quejada Duran | O4: oquejada@sena.edu.co | P4: 3218304193 | Q4: 44223 | R4: Propia | S4: N/A | T4: N/A
A5: =_xlfn.CONCAT(TBL_Sedes[[#This Row],[Ciudad]]," ",TBL_Sedes[[#This Row],[Nombre de la sede]]) -> Arauca Centro De Gestión Y Desarrollo Agroindustrial De Arauca | B5: 167A | C5: 95301000 | D5: Arauca | E5: Arauca | F5: Centro De Gestión Y Desarrollo Agroindustrial De Arauca | G5: Carrera 20 No.28-163 | H5: Centro De Formación | I5: A | J5: 06:00 A 22:00 | K5: N/A | L5: N/A | M5: Activa | N5: Andres Felipe Monroy Amaya | O5: afmonroy@sena.edu.co | P5: 3144351804 | Q5: 74220 | R5: Arriendo | S5: 2021-01-26T05:00:00.000Z | T5: 2023-12-31T04:59:59.000Z
A6: =_xlfn.CONCAT(TBL_Sedes[[#This Row],[Ciudad]]," ",TBL_Sedes[[#This Row],[Nombre de la sede]]) -> Arauca Escuela De Gastronomía | B6: 306 | C6: 95301005 | D6: Arauca | E6: Arauca | F6: Escuela De Gastronomía | G6: Calle 1 # 1-130 Matevenado | H6: Subsede Cstic | I6: C | J6: 8:00 – 17:00 | K6: N/A | L6: N/A | M6: Activa | N6: Andres Felipe Monroy Amaya | O6: afmonroy@sena.edu.co | P6: 3144351804 | Q6: 74220 | R6: Propia | S6: N/A | T6: N/A
A7: =_xlfn.CONCAT(TBL_Sedes[[#This Row],[Ciudad]]," ",TBL_Sedes[[#This Row],[Nombre de la sede]]) -> Arauca Regional Arauca | B7: 167 | C7: 10108100 | D7: Arauca | E7: Arauca | F7: Regional Arauca | G7: Carrera 20 No.28-163 | H7: Regional | I7: A | J7: 06:00 A 22:00 | K7: N/A | L7: N/A | M7: Activa | N7: Andres Felipe Monroy Amaya | O7: afmonroy@sena.edu.co | P7: 3144351804 | Q7: 74220 | R7: Propia | S7: N/A | T7: N/A
A8: =_xlfn.CONCAT(TBL_Sedes[[#This Row],[Ciudad]]," ",TBL_Sedes[[#This Row],[Nombre de la sede]]) -> Arauca Tecnoacademia Arauca | B8: 313 | C8: 95301005 | D8: Arauca | E8: Arauca | F8: Tecnoacademia Arauca | G8: Calle 18 # 44-65 | H8: Subsede Cstic | I8: C | J8: 7:00 - 19:00 | K8: 7:00 - 12:00 | L8: N/A | M8: Activa | N8: Andres Felipe Monroy Amaya | O8: afmonroy@sena.edu.co | P8: 3144351804 | Q8: 74220 | R8: Arriendo | S8: 2021-02-15T05:00:00.000Z | T8: 2021-12-31T04:59:59.000Z
A9: =_xlfn.CONCAT(TBL_Sedes[[#This Row],[Ciudad]]," ",TBL_Sedes[[#This Row],[Nombre de la sede]]) -> Arauca Unidad De Emprendimiento Y Agencia Pública De Empleo | B9: 240 | C9: 95301003 | D9: Arauca | E9: Arauca | F9: Unidad De Emprendimiento Y Agencia Pública De Empleo | G9: Calle 24 No. 19-17 Barrio Córdoba | H9: Subsede Cstic | I9: C | J9: 06:00 A 22:00 | K9: N/A | L9: N/A | M9: Activa | N9: Andres Felipe Monroy Amaya | O9: afmonroy@sena.edu.co | P9: 3144351804 | Q9: 74220 | R9: Propia | S9: N/A | T9: N/A
A10: =_xlfn.CONCAT(TBL_Sedes[[#This Row],[Ciudad]]," ",TBL_Sedes[[#This Row],[Nombre de la sede]]) -> Arauquita Granja El Alcaraván Arauquita | B10: 241 | C10: 95301004 | D10: Arauca | E10: Arauquita | F10: Granja El Alcaraván Arauquita | G10: Vereda Campo Alegre, Predios Mundo Nuevo 1 Y Mundo Nuevo 2 | H10: Subsede Cstic | I10: C | J10: 06:00 A 22:00 | K10: N/A | L10: N/A | M10: Activa | N10: Andres Felipe Monroy Amaya | O10: afmonroy@sena.edu.co | P10: 3144351804 | Q10: 74220 | R10: Propia | S10: N/A | T10: N/A
A11: =_xlfn.CONCAT(TBL_Sedes[[#This Row],[Ciudad]]," ",TBL_Sedes[[#This Row],[Nombre de la sede]]) -> Armenia Centro Agroindustrial | B11: 132A | C11: 91201000 | D11: Quindío | E11: Armenia | F11: Centro Agroindustrial | G11: Carrera 6, Avenida Centenario 44 N - 15 | H11: Centro De Formación | I11: A | J11: 07:00 A 18:00 | K11: N/A | L11: N/A | M11: Suspendida Parcial | N11: Jose Alexander Bermudez | O11: jalexanderb@sena.edu.co | P11: 3127992702 | Q11: 62815 | R11: Propia | S11: N/A | T11: N/A
A12: =_xlfn.CONCAT(TBL_Sedes[[#This Row],[Ciudad]]," ",TBL_Sedes[[#This Row],[Nombre de la sede]]) -> Armenia Centro De Comercio, Industria Y Turismo | B12: 131 | C12: 95381000 | D12: Quindío | E12: Armenia | F12: Centro De Comercio, Industria Y Turismo | G12: Carrera 18 No. 7-58 | H12: Centro De Formación | I12: A | J12: 06:00 A 19:00 | K12: 06:00 A 18:00 | L12: N/A | M12: Activa | N12: Mario Alexander Ruiz Marulanda | O12: maruizm@sena.edu.co | P12: 315 3310808 | Q12: 62670
A13: =_xlfn.CONCAT(TBL_Sedes[[#This Row],[Ciudad]]," ",TBL_Sedes[[#This Row],[Nombre de la sede]]) -> Armenia Centro para el desarrollo tecnológico de la construcción y la industria | B13: 197 | C13: 92311000 | D13: Quindío | E13: Armenia | F13: Centro para el desarrollo tecnológico de la construcción y la industria | G13: Carrera 6 N° 47N - 15 | H13: Centro De Formación | I13: A | J13: 07:00 A 22:00 | K13: 07:00 A 13:00 | L13: N/A | M13: Activa | N13: Juan Bautista Londoño Pineda | O13: jlondonop@sena.edu.co | P13: 310 3812240 | Q13: 62948 | R13: Propia | S13: N/A | T13: N/A
A14: =_xlfn.CONCAT(TBL_Sedes[[#This Row],[Ciudad]]," ",TBL_Sedes[[#This Row],[Nombre de la sede]]) -> Armenia Regional Quindío | B14: 132 | C14: 10106300 | D14: Quindío | E14: Armenia | F14: Regional Quindío | G14: Avenida Centenario 42N-02 | H14: Regional | I14: A | J14: 06:00 A 19:00 | K14: N/A | L14: N/A | M14: Suspendida Parcial | N14: John Freddy Villalba | O14: jfvillalba@sena.edu.co | P14: 3103936263 | Q14: 62873
A15: =_xlfn.CONCAT(TBL_Sedes[[#This Row],[Ciudad]]," ",TBL_Sedes[[#This Row],[Nombre de la sede]]) -> Armenia Tecnoacademia Armenia | B15: 330 | C15: 91201050 | D15: Quindío | E15: Armenia | F15: Tecnoacademia Armenia | G15: Barrio Puerto Espejo, Manzana # 11 | H15: Subsede Sstic | I15: C | J15: 07:00 A 19:00 | K15: 08:00 A 12:00 | L15: N/A | M15: Activa | N15: Jose Alexandet Bermudez | O15: jalexanderb@sena.edu.co | P15: 3127992702 | Q15: 62815
A16: =_xlfn.CONCAT(TBL_Sedes[[#This Row],[Ciudad]]," ",TBL_Sedes[[#This Row],[Nombre de la sede]]) -> Baranoa Nodo de Confecciones | B16: 351 | C16: 92081004 | D16: Atlántico | E16: Baranoa | F16: Nodo de Confecciones | G16: Transversal 21 # 11 - 140 (Av. Cordialidad) | H16: Subsede CSTIC | I16: C | J16: 7:00 - 18:00 | K16: 8:00-14:00 | L16: N/A | M16: Implementación | N16: Benjamin Pedrozo Rocha | O16: bepedrozor@sena.edu.co | P16: 3116568942 | Q16: 52300
A17: =_xlfn.CONCAT(TBL_Sedes[[#This Row],[Ciudad]]," ",TBL_Sedes[[#This Row],[Nombre de la sede]]) -> Barrancabermeja Centro De Desarrollo Vecinal Cdv | B17: 336 | C17: 95401050 | D17: Santander | E17: Barrancabermeja | F17: Centro De Desarrollo Vecinal Cdv | G17: Calle 58 29-57 | H17: Subsede Sstic | I17: C | J17: 06:00 A 21:00 | K17: N/A | L17: N/A | M17: Activa | N17: Sergio Samuel Jaimes Muñoz | O17: ssjaimes@sena.edu.co | P17: 3205763757 | Q17: 73658
A18: =_xlfn.CONCAT(TBL_Sedes[[#This Row],[Ciudad]]," ",TBL_Sedes[[#This Row],[Nombre de la sede]]) -> Barrancabermeja Centro Industrial Y Del Desarrollo Tecnológico | B18: 143 | C18: 95401000 | D18: Santander | E18: Barrancabermeja | F18: Centro Industrial Y Del Desarrollo Tecnológico | G18: Carrera 28 # 56 - 10 Barrio Galan | H18: Centro De Formación | I18: A | J18: 06:00 A 21:00 | K18: 18:00 A 21:00 | L18: N/A | M18: Activa | N18: Sergio Samuel Jaimes Muñoz | O18: ssjaimes@sena.edu.co | P18: 3205763757 | Q18: 73658 | R18: Propia | S18: N/A | T18: N/A
A19: =_xlfn.CONCAT(TBL_Sedes[[#This Row],[Ciudad]]," ",TBL_Sedes[[#This Row],[Nombre de la sede]]) -> Barranquilla Centro De Comercio Y Servicios | B19: 19A | C19: 93021000 | D19: Atlántico | E19: Barranquilla | F19: Centro De Comercio Y Servicios | G19: Carrera 43 42-40 Piso 10 | H19: Centro De Formación | I19: A | J19: 07:00 A 19:00 | K19: N/A | L19: N/A | M19: Activa | N19: Jorge Pinedo | O19: jpinedo@sena.edu.co | P19: 3024012301 | Q19: 52734
A20: =_xlfn.CONCAT(TBL_Sedes[[#This Row],[Ciudad]]," ",TBL_Sedes[[#This Row],[Nombre de la sede]]) -> Barranquilla Centro Industrial Y De Aviación | B20: 21A | C20: 92081000 | D20: Atlántico | E20: Barranquilla | F20: Centro Industrial Y De Aviación | G20: Calle 30 3E-164 | H20: Centro De Formación | I20: A | J20: 00:00 A 00:00 | K20: 06:30 A 16:00 | L20: N/A | M20: Activa | N20: Benjamin Pedrozo Rocha | O20: bepedrozor@sena.edu.co | P20: 3116568942 | Q20: 52300
A21: =_xlfn.CONCAT(TBL_Sedes[[#This Row],[Ciudad]]," ",TBL_Sedes[[#This Row],[Nombre de la sede]]) -> Barranquilla Centro Nacional Colombo Alemán | B21: 21 | C21: 92071000 | D21: Atlántico | E21: Barranquilla | F21: Centro Nacional Colombo Alemán | G21: Calle 30 3E-164 | H21: Centro De Formación | I21: A | J21: 06:00 A 22:00 | K21: 06:30 A 18:00 | L21: N/A | M21: Activa | N21: Benjamin Pedrozo Rocha | O21: bepedrozor@sena.edu.co | P21: 3116568942 | Q21: 52300 | R21: Propia | S21: N/A | T21: N/A
A22: =_xlfn.CONCAT(TBL_Sedes[[#This Row],[Ciudad]]," ",TBL_Sedes[[#This Row],[Nombre de la sede]]) -> Barranquilla Hangar Caribe Verde | B22: 352 | C22: 92081005 | D22: Atlántico | E22: Barranquilla | F22: Hangar Caribe Verde | G22: Carrera 9G No 110-187 Lote 10 y 11 Caribe Verde | H22: Subsede CSTIC | I22: C | J22: 07:00-18:00 | K22: N/A | L22: N/A | M22: Activa | N22: Jorge Pinedo | O22: jpinedo@sena.edu.co | P22: 3024012301 | Q22: 52300/52243
A23: =_xlfn.CONCAT(TBL_Sedes[[#This Row],[Ciudad]]," ",TBL_Sedes[[#This Row],[Nombre de la sede]]) -> Barranquilla Logística Y Transporte | B23: 273 | C23: 93021001 | D23: Atlántico | E23: Barranquilla | F23: Logística Y Transporte | G23: Carrera 9 No. 127-109 | H23: Subsede Cstic | I23: B | J23: 07:00 A 17:30 | K23: N/A | L23: N/A | M23: Activa | N23: Jorge Pinedo | O23: jpinedo@sena.edu.co | P23: 3024012301 | Q23: 52734
A24: =_xlfn.CONCAT(TBL_Sedes[[#This Row],[Ciudad]]," ",TBL_Sedes[[#This Row],[Nombre de la sede]]) -> Barranquilla Nodo Construcción E Infraestructura | B24: 272 | C24: 92081001 | D24: Atlántico | E24: Barranquilla | F24: Nodo Construcción E Infraestructura | G24: Villas De San Pablo, Super Manzana Equipamento Institucional Mf Eq & Lote Fundación Santo Domingo | H24: Subsede Cstic | I24: B | J24: 07:00 A 17:30 | K24: N/A | L24: N/A | M24: Activa | N24: Benjamin Pedrozo Rocha | O24: bepedrozor@sena.edu.co | P24: 3116568942 | Q24: 52300 | R24: Propio no explotado | S24: N/A | T24: N/A
A25: =_xlfn.CONCAT(TBL_Sedes[[#This Row],[Ciudad]]," ",TBL_Sedes[[#This Row],[Nombre de la sede]]) -> Barranquilla Nodo De Hotelería Y Turismo | B25: 287 | C25: 93021002 | D25: Atlántico | E25: Barranquilla | F25: Nodo De Hotelería Y Turismo | G25: Carrera 39 Calle 50 Diagonal A La Aduana | H25: Subsede Cstic | I25: C | J25: 07:00 A 17:30 | K25: N/A | L25: N/A | M25: Activa | N25: Jorge Pinedo | O25: jpinedo@sena.edu.co | P25: 3024012301 | Q25: 52734
A26: =_xlfn.CONCAT(TBL_Sedes[[#This Row],[Ciudad]]," ",TBL_Sedes[[#This Row],[Nombre de la sede]]) -> Barranquilla Nodo De Industrias Creativas | B26: 288 | C26: 91031002 | D26: Atlántico | E26: Barranquilla | F26: Nodo De Industrias Creativas | G26: Carrera 54 # 49 - 09 Colegio Esther De Pelaez (Al Lado De La Casadel Carnaval) | H26: Subsede Cstic | I26: C | J26: 07:00 A 17:30 | K26: N/A | L26: N/A | M26: Activa | N26: Benjamin Pedrozo Rocha | O26: bepedrozor@sena.edu.co | P26: 3116568942 | Q26: 52300 | R26: Propia | S26: N/A | T26: N/A
A27: =_xlfn.CONCAT(TBL_Sedes[[#This Row],[Ciudad]]," ",TBL_Sedes[[#This Row],[Nombre de la sede]]) -> Barranquilla Nodo Multilingüismo | B27: 290 | C27: 92081002 | D27: Atlántico | E27: Barranquilla | F27: Nodo Multilingüismo | G27: Carrera 21B, Calle 40B Esquina Barrio San José | H27: Subsede Cstic | I27: C | J27: 07:00 A 17:30 | K27: N/A | L27: N/A | M27: Activa | N27: Benjamin Pedrozo Rocha | O27: bepedrozor@sena.edu.co | P27: 3116568942 | Q27: 52300 | R27: Propia | S27: N/A | T27: N/A
A28: =_xlfn.CONCAT(TBL_Sedes[[#This Row],[Ciudad]]," ",TBL_Sedes[[#This Row],[Nombre de la sede]]) -> Barranquilla Nodo Refrigeración | B28: 289 | C28: 92071004 | D28: Atlántico | E28: Barranquilla | F28: Nodo Refrigeración | G28: Carrera 10 # 7E-110 Antiguo Coliseo Del Sur | H28: Subsede Cstic | I28: C | J28: 07:00 A 17:30 | K28: N/A | L28: N/A | M28: Activa | N28: Benjamin Pedrozo Rocha | O28: bepedrozor@sena.edu.co | P28: 3116568942 | Q28: 52300 | R28: Propia | S28: N/A | T28: N/A
A29: =_xlfn.CONCAT(TBL_Sedes[[#This Row],[Ciudad]]," ",TBL_Sedes[[#This Row],[Nombre de la sede]]) -> Barranquilla Nodo Salud | B29: 271 | C29: 93021003 | D29: Atlántico | E29: Barranquilla | F29: Nodo Salud | G29: Calle 33 # 33 139 Hospital Barranquilla | H29: Subsede Cstic | I29: B | J29: 07:00 A 17:30 | K29: N/A | L29: N/A | M29: Activa | N29: Jorge Pinedo | O29: jpinedo@sena.edu.co | P29: 3024012301 | Q29: 52734 | R29: Propio no explotado | S29: N/A | T29: N/A
A30: =_xlfn.CONCAT(TBL_Sedes[[#This Row],[Ciudad]]," ",TBL_Sedes[[#This Row],[Nombre de la sede]]) -> Barranquilla Nodo Servicios Administrativos | B30: 297 | C30: 93021004 | D30: Atlántico | E30: Barranquilla | F30: Nodo Servicios Administrativos | G30: CARRERA 6 # 60B-110 | H30: Subsede CSTIC | I30: C | J30: 7:00 - 19:00 | K30: N/A | L30: N/A | M30: Activa | N30: Jorge Pinedo | O30: jpinedo@sena.edu.co | P30: 3024012301 | Q30: 52734 | S30: 2021-01-02T05:00:00.000Z | T30: 2023-12-31T04:59:59.000Z
A31: =_xlfn.CONCAT(TBL_Sedes[[#This Row],[Ciudad]]," ",TBL_Sedes[[#This Row],[Nombre de la sede]]) -> Barranquilla Nodo Servicios Financieros | B31: 298 | C31: 93021005 | D31: Atlántico | E31: Barranquilla | F31: Nodo Servicios Financieros | G31: Av. Circunvalar Junto Al Colegio Las Cayenas Kra. 15 Sur # 46 -500 | H31: Subsede Cstic | I31: C | J31: 7:00 - 17:00 | K31: N/A | L31: N/A | M31: Activa | N31: Jorge Pinedo | O31: jpinedo@sena.edu.co | P31: 3024012301 | Q31: 52734
A32: =_xlfn.CONCAT(TBL_Sedes[[#This Row],[Ciudad]]," ",TBL_Sedes[[#This Row],[Nombre de la sede]]) -> Barranquilla Nodo Tic Barranquilla | B32: 303 | C32: 92071003 | D32: Atlántico | E32: Barranquilla | F32: Nodo Tic Barranquilla | G32: Carrera 54 # 68-80 | H32: Subsede Cstic | I32: C | J32: 7:00 - 17:00 | K32: N/A | L32: N/A | M32: Activa | N32: Benjamin Pedrozo Rocha | O32: bepedrozor@sena.edu.co | P32: 3116568942 | Q32: 52300 | R32: Propio no explotado | S32: N/A | T32: N/A
A33: =_xlfn.CONCAT(TBL_Sedes[[#This Row],[Ciudad]]," ",TBL_Sedes[[#This Row],[Nombre de la sede]]) -> Barranquilla Regional Atlántico | B33: 19 | C33: 10100800 | D33: Atlántico | E33: Barranquilla | F33: Regional Atlántico | G33: Carrera 43 42-40 Piso 11 | H33: Regional | I33: A | J33: 07:00 A 19:00 | K33: 08:00 A 12:00 | L33: N/A | M33: Activa | N33: Jorge Pinedo | O33: jpinedo@sena.edu.co | P33: 3024012301 | Q33: 52734 | R33: Propia | S33: N/A | T33: N/A
A34: =_xlfn.CONCAT(TBL_Sedes[[#This Row],[Ciudad]]," ",TBL_Sedes[[#This Row],[Nombre de la sede]]) -> Barranquilla Sede Energía | B34: 251 | C34: 92071002 | D34: Atlántico | E34: Barranquilla | F34: Sede Energía | G34: Calle 28 # 23-18 Barrio Montes | H34: Subsede Cstic | I34: B | J34: 07:00 A 17:30 | K34: N/A | L34: N/A | M34: Activa | N34: Benjamin Pedrozo Rocha | O34: bepedrozor@sena.edu.co | P34: 3116568942 | Q34: 52300
A35: =_xlfn.CONCAT(TBL_Sedes[[#This Row],[Ciudad]]," ",TBL_Sedes[[#This Row],[Nombre de la sede]]) -> Bogotá Centro De Diseño Y Metrología - Complejo Paloquemao | B35: 25A | C35: 92161000 | D35: Distrito Capital | E35: Bogotá | F35: Centro De Diseño Y Metrología - Complejo Paloquemao | G35: Carrera 31 No 14-20 | H35: Centro De Formación | I35: A | J35: 06:00 A 22:00 | K35: 07:00 A 14:00 | L35: N/A | M35: Activa | N35: Julia Elvira Cerinza Blanco | O35: jcerinza@sena.edu.co | P35: 313 8459443 | Q35: 15730
A36: =_xlfn.CONCAT(TBL_Sedes[[#This Row],[Ciudad]]," ",TBL_Sedes[[#This Row],[Nombre de la sede]]) -> Bogotá Centro De Electricidad, Electrónica Y Telecomunicaciones - Complejo Sur | B36: 24 | C36: 92101000 | D36: Distrito Capital | E36: Bogotá | F36: Centro De Electricidad, Electrónica Y Telecomunicaciones - Complejo Sur | G36: Avenida 30 No 17B-25 Sur | H36: Centro De Formación | I36: A | J36: 06:00 A 22:00 | K36: 06:00 A 18:00 | L36: 06:00 A 18:00 | M36: Activa | N36: Wendy Julieth Rodríguez Nieves | O36: wjrodriguezn@sena.edu.co | P36: 3124063029 | Q36: 15386 | R36: Propia | S36: N/A | T36: N/A
A37: =_xlfn.CONCAT(TBL_Sedes[[#This Row],[Ciudad]]," ",TBL_Sedes[[#This Row],[Nombre de la sede]]) -> Bogotá Centro De Formación De Talento Humano En Salud | B37: 28 | C37: 94031000 | D37: Distrito Capital | E37: Bogotá | F37: Centro De Formación De Talento Humano En Salud | G37: Carrera 6 No. 45 - 52 | H37: Centro De Formación | I37: B | J37: 06:00 A 22:00 | K37: 06:00 A 18:00 | L37: N/A | M37: Activa | N37: Carlos Andres Valencia | O37: valenciab@sena.edu.co | P37: 3187632371 | Q37: 15947 | R37: Propia | S37: N/A | T37: N/A
A38: =_xlfn.CONCAT(TBL_Sedes[[#This Row],[Ciudad]]," ",TBL_Sedes[[#This Row],[Nombre de la sede]]) -> Bogotá Centro de formación en actividad física y cultura - Onassis | B38: 31 | C38: 95081001 | D38: Distrito Capital | E38: Bogotá | F38: Centro de formación en actividad física y cultura - Onassis | G38: Tranv 82 # 44-37 Sur | H38: Subsede Cstic | I38: C | J38: 06:00 A 22:00 | K38: N/A | L38: N/A | M38: Activa | N38: Marvin Avila Careth | O38: acareth@sena.edu.co | P38: 3188928707 | R38: Comodato
A39: =_xlfn.CONCAT(TBL_Sedes[[#This Row],[Ciudad]]," ",TBL_Sedes[[#This Row],[Nombre de la sede]]) -> Bogotá Centro De Formación En Actividad Física Y Cultura-Kennedy | B39: 37 | C39: 95081000 | D39: Distrito Capital | E39: Bogotá | F39: Centro De Formación En Actividad Física Y Cultura-Kennedy | G39: Transversal 78 J No 41D-15 Sur Kennedy | H39: Centro De Formación | I39: B | J39: 06:00 A 22:00 | K39: N/A | L39: N/A | M39: Activa | N39: Marvin Avila Careth | O39: acareth@sena.edu.co | P39: 3188928707 | R39: Propia | S39: N/A | T39: N/A
A40: =_xlfn.CONCAT(TBL_Sedes[[#This Row],[Ciudad]]," ",TBL_Sedes[[#This Row],[Nombre de la sede]]) -> Bogotá Centro De Gestión Administrativa | B40: 30 | C40: 94041000 | D40: Distrito Capital | E40: Bogotá | F40: Centro De Gestión Administrativa | G40: Avenida Carracas No 13-88 | H40: Centro De Formación | I40: A | J40: L-V 06:00 A 22:00, martes, miercoles y jueves 24 Horas | K40: 06:00 A 22:00 | L40: 06:00 A 22:00 | M40: Activa | N40: Gloria del Pilar Bernal Peña | O40: gbernal@sena.edu.co | P40: 3138028393 | Q40: 16007 | R40: Propia | S40: N/A | T40: N/A
A41: =_xlfn.CONCAT(TBL_Sedes[[#This Row],[Ciudad]]," ",TBL_Sedes[[#This Row],[Nombre de la sede]]) -> Bogotá Centro De Gestión De Mercados, Logística Y Tecnologías De La Información | B41: 42 | C41: 93031000 | D41: Distrito Capital | E41: Bogotá | F41: Centro De Gestión De Mercados, Logística Y Tecnologías De La Información | G41: Calle 52 No 13-65 | H41: Centro De Formación | I41: A | J41: 07:00 A 22:00 | K41: 07:00 A 12:00 | L41: N/A | M41: Suspendida Parcial | N41: Darwin Bolivar | O41: dbolivar@sena.edu.co | P41: 301 6518099 | Q41: 16979 | R41: Propia | S41: N/A | T41: N/A
...

Sheet Instrucciones
I1: Versión: 06
I2: Código: GTI-F-029
A3: PROCESO | J3: Versión: 05
A4: Gestión de Tecnologías de la Información
A5: NOMBRE DEL FORMATO
A6: Formato de Petición de Accesos Directorio Activo y Correo Electrónico
A7: CLASIFICACIÓN DE LA INFORMACIÓN
A8: Pública | C8: Pública Clasificada | F8: Pública Reservada
A9: INSTRUCCIONES PARA EL DILIGENCIAMIENTO DEL FORMATO
A10: NO IMPRIMIR
A11: 1. Generalidades
A12: a) Objetivo del formato: Crear cuentas de correo electrónico y usuario de directorio activo
A13: b) ¿Si hay un procedimiento que refiera este formato?: GTI-GO-016 Guía operacional Gestión de Accesos
A14: c) ¿Quién(es) lo diligencian?:Líderes TIC y funcionarios SENA
A15: d) Frecuencia de diligenciamiento: Por demanda
A16: e) Qué trámite surte el formato una vez diligenciado: Se envía a la Mesa de Servicios
A17: f) Si se requiere imprimir: No
A18: g) Quién lo guarda: Se adjunta al caso en la herramienta de gestión
A19: 2. Instrucciones para diligenciar las casillas
A21: NOMBRE DE LA CASILLA | B21: INSTRUCCIONES | F21: TENER EN CUENTA
A22: Datos del Autorizador
A23: Nombres | B23: Diligencie los nombres del autorizador
A24: Apellidos | B24: Diligencie los apellidos del autorizador
A25: Correo electrónico | B25: Diligencie el correo electrónico
A26: Regional | B26: Diligencie los datos de la regional
A27: Ubicación | B27: Diligencie la ubicación del autorizador
A28: Solicitud de Cuentas de Red y Correo
A29: No. | B29: Número consecutivo de 1 a N.
A30: Tipo de solicitud | B30: Seleccione el tipo de solicitud: - Crear: El funcionario es nuevo - Modificar: La cuenta existe y se va a modificar algún parámetro - Activar: La cuenta existe pero se encuentra caducada - Inactivar: Se requiere inactivar alguna cuenta existente | F30: Campo obligatorio
A31: Correo electrónico Institucional | B31: Diligencie el correo electrónico institucional. Solo para modificar, activar o eliminar. | F31: En caso de que el tipo de solicitud sea "Crear", por favor no diligenciar o dejar en blanco esta celda. En caso de ser cuenta genérica coloque el nombre propuesto para la cuenta genérica. El nombre propuesto debe contener menos de 20 caracteres antes del @sena.edu.co
A32: Nombres | B32: Diligencie los nombres del funcionario. | F32: En caso de ser cuenta genérica diligencie los nombres del responsable. Campo obligatorio
A33: Apellidos | B33: Diligencie los apellidos del funcionario. | F33: En caso de ser cuenta genérica diligencie los apellidos del responsable. Campo obligatorio
A34: Documento de Identidad | B34: Diligencie el documento de identidad. | F34: Campo obligatorio
A35: Número Celular | B35: Diligencie el número celular | F35: Campo obligatorio
A36: Correo Personal | B36: Diligencie el correo electrónico personal | F36: Campo obligatorio
A37: Tipo de vinculación | B37: Seleccione de la lista desplegable | F37: Campo obligatorio
A38: Cargo | B38: Seleccione de la lista desplegable | F38: Si su tipo de vinculación pertenece a Contratista por políticas del SENA su Rol / Cargo es Contratista. Campo obligatorio
A39: Rol | B39: Seleccione de la lista desplegable | F39: Seleccione su rol dentro de la entidad
A40: ID sede | B40: Relacione el id sede a la cual pertenece | F40: No modificar
A41: Regional | B41: Relacione la regional de la sede a la cual pertenece | F41: No modificar
...

Sheet f
S1: Versión: 04
S2: Código: GTI-F-029
A3: Gestión de Tecnologías de la Información
A4: Formato de petición de accesos de directorio activo y correo electrónico
A5: 1. Datos del autorizador
A6: Nombres | E6: Apellidos | I6: Correo electrónico del autorizador (@sena.edu.co) | P6: Ubicación
A7: José Wilson | E7: Carrero Maldonado | I7: jcarrero@sena.edu.co | L7: Regional Santander | P7: Despacho Regional ( e )
A8: 2. Solicitud de Cuentas de Red y Correo
A9: No. | B9: Tipo De Solicitud | C9: Correo electrónico institucional (@sena.edu.co) | D9: Nombres | E9: Apellidos | F9: Documento de identidad | G9: Número celular | H9: Correo personal | I9: Tipo de vinculación | J9: Cargo | K9: Rol | L9: Nombre sede | M9: Dirección sede | N9: ID sede | O9: Regional | P9: Número EXT (IP) | Q9: Fecha de terminación de contrato (dd/mm/yy) | R9: VPN | S9: Observaciones/Descripción | T9: Observaciones/Descripción | U9: Funtion Concatenar | V9: Function Ubicación | W9: Funtion PBX
A10: 1 | M10: =VLOOKUP(L10,SEDES!A:T,7,) | N10: =VLOOKUP(L10,SEDES!A:T,2,) | O10: =VLOOKUP(L10,SEDES!A:T,4,)
A11: 2 | M11: =VLOOKUP(L11,SEDES!A:T,7,) | N11: =VLOOKUP(L11,SEDES!A:T,2,) | O11: =VLOOKUP(L11,SEDES!A:T,4,)
A12: 3 | M12: =VLOOKUP(L12,SEDES!A:T,7,) | N12: =VLOOKUP(L12,SEDES!A:T,2,) | O12: =VLOOKUP(L12,SEDES!A:T,4,)
A13: 4 | M13: =VLOOKUP(L13,SEDES!A:T,7,) | N13: =VLOOKUP(L13,SEDES!A:T,2,) | O13: =VLOOKUP(L13,SEDES!A:T,4,)
A14: 5 | M14: =VLOOKUP(L14,SEDES!A:T,7,) | N14: =VLOOKUP(L14,SEDES!A:T,2,) | O14: =VLOOKUP(L14,SEDES!A:T,4,)
A15: 6 | M15: =VLOOKUP(L15,SEDES!A:T,7,) | N15: =VLOOKUP(L15,SEDES!A:T,2,) | O15: =VLOOKUP(L15,SEDES!A:T,4,)
A16: 7 | M16: =VLOOKUP(L16,SEDES!A:T,7,) | N16: =VLOOKUP(L16,SEDES!A:T,2,) | O16: =VLOOKUP(L16,SEDES!A:T,4,)
A17: 8 | M17: =VLOOKUP(L17,SEDES!A:T,7,) | N17: =VLOOKUP(L17,SEDES!A:T,2,) | O17: =VLOOKUP(L17,SEDES!A:T,4,)
A18: 9 | M18: =VLOOKUP(L18,SEDES!A:T,7,) | N18: =VLOOKUP(L18,SEDES!A:T,2,) | O18: =VLOOKUP(L18,SEDES!A:T,4,)
A19: 10 | M19: =VLOOKUP(L19,SEDES!A:T,7,) | N19: =VLOOKUP(L19,SEDES!A:T,2,) | O19: =VLOOKUP(L19,SEDES!A:T,4,)
A20: 21 | M20: =VLOOKUP(L20,SEDES!A:T,7,) | N20: =VLOOKUP(L20,SEDES!A:T,2,) | O20: =VLOOKUP(L20,SEDES!A:T,4,)
A21: 22 | M21: =VLOOKUP(L21,SEDES!A:T,7,) | N21: =VLOOKUP(L21,SEDES!A:T,2,) | O21: =VLOOKUP(L21,SEDES!A:T,4,)
... A49: 50 | M49: =VLOOKUP(L49,SEDES!A:T,7,) | N49: =VLOOKUP(L49,SEDES!A:T,2,) | O49: =VLOOKUP(L49,SEDES!A:T,4,)
A50: 3. Solicitud de Cuentas de Correo Genéricas | J50: Justificación de la Solicitud para Cuentas de correo genéricas
A51: No. | B51: Tipo de Solicitud | C51: Nombre propuesto | D51: Responsable | F51: Correo Institucional del responsable
A52: 1
A53: 2
A54: 3
A55: 4
A56: 5
A57: RESPONSABILIDADES: Este documento debe estar debidamente diligenciado y deberá ser enviado a la MESA DE SERVICIO (mesadeservicio@sena.edu.co), teniendo la aprobación del Usuario Autorizador. Favor tener en cuenta las siguientes observaciones: • El usuario tendrá 16 horas hábiles para notificar al Usuario Autorizador o a la Mesa de servicio la funcionalidad de los accesos otorgados por correo electrónico, pasado este tiempo se dará por aceptado y cerrado. • La custodia de las solicitudes reposará en la MESA DE SERVICIO. • Todos los campos del formato deben diligenciarse de acuerdo con el tipo de solicitud (Cuenta de red y correo o Cuentas de correo genéricas) en su totalidad a menos que el campo indique lo contrario.
U83: Regionales | V83: Dirección General | W83: Regional Amazonas | X83: Regional Antioquia | Y83: Regional Arauca | Z83: Regional Atlántico | AA83: Regional Bolivar | AB83: Regional Boyacá | AC83: Regional Caldas | AD83: Regional Caquetá | AE83: Regional Casanare | AF83: Regional Cauca | AG83: Regional Cesar | AH83: Regional Chocó | AI83: Regional Cordoba | AJ83: Regional Cundinamarca | AK83: Regional Distrito Capital | AL83: Regional Guainía | AM83: Regional Guajira | AN83: Regional Guaviare | AO83: Regional Huila | AP83: Regional Magdalena | AQ83: Regional Meta | AR83: Regional Nariño | AS83: Regional Norte De Santander | AT83: Regional Putumayo | AU83: Regional Quindío | AV83: Regional Risaralda | AW83: Regional San Andres | AX83: Regional Santander | AY83: Regional Sucre | AZ83: Regional Tolima | BA83: Regional Valle | BB83: Regional Vaupés | BC83: Regional Vichada | BD83: Dirección Administrativa Y Financiera
U84: Dirección General | V84: Dirección General | W84: Regional Amazonas | X84: Regional Antioquia | Y84: Regional Arauca | Z84: Regional Atlántico | AA84: Sede Casa Del Marqués | AB84: Sede Chiquinquirá | AC84: Regional Caldas | AD84: Regional Caquetá | AE84: Regional Casanare | AF84: Regional Cauca | AG84: Regional Cesar | AH84: Regional Chocó | AI84: Regional Córdoba | AJ84: Regional Cundinamarca | AK84: Regional Distrito Capital | AL84: Regional Guainía | AM84: Regional Guajira | AN84: Centro De Desarrollo Agroindustrial, Turístico Y Tecnológico Del Guaviare Sede Centro | AO84: Regional Huila | AP84: Centro De Logística Y Promoción Ecoturística Del Magdalena | AQ84: Regional Meta | AR84: Regional Nariño | AS84: Sede Grupo Pamplona | AT84: Regional Putumayo | AU84: Centro De Comercio, Industria Y Turismo | AV84: Regional Risaralda | AW84: Regional San Andrés | AX84: Regional Santander | AY84: Regional Sucre | AZ84: Centro De Industria Y La Construcción | BA84: Regional Valle | BB84: Regional Vaupés | BC84: Regional Vichada | BD84: Sindesena
U85: Regional Amazonas | V85: Escuela De Instructores | W85: Centro Para La Biodiversidad Y El Turismo Del Amazonas | X85: Tecnoparque Colombia Nodo Medellín | Y85: Sede Tame | Z85: Centro Para El Desarrollo Agroecológico Y Agroindustrial | AA85: Regional Bolívar | AB85: Sede DuitamaCiudadela Industrial | AC85: Spe Manizales | AD85: Centro Tecnológico De La Amazonia | AE85: Sede Paz De Ariporo | AF85: Centro Agropecuario | AG85: Sede Jagua De Ibirico | AH85: Istmina | AI85: SedeLorica | AJ85: Centro De Desarrollo Agroindustrial Y Empresarial | AK85: Sede San Antonio | AL85: Centro Ambiental Y Ecoturístico Del Nororiente Amazónico | AM85: Sede Industrial | AN85: Regional Guaviare | AO85: Sede Industrial | AP85: IpcCentro De Logística Y Promoción Ecoturística Del Magdalena | AQ85: Sede El Hachon | AR85: Spe Pasto | AS85: Sede Grupo Ocaña | AT85: Sede Mocoa | AU85: Regional Quindío | AV85: Sede Centro De Pereira | AW85: Sede Providencia | AX85: Centro Atención Sector Agropecuario | AY85: Sede Escuela Gastronómica | AZ85: Regional Tolima | BA85: Spe Cali | BB85: Sede Cuervo Araoz | BC85: Aula ItineranteCumaribo
U86: Regional Antioquia | V86: Sede ColonSintrasena | X86: Centro De Los Recursos Naturales Renovables La Salada | Y86: Sede Saravena | Z86: Centro Nacional Colombo Alemán | AA86: Sede San Jacinto | AB86: Regional Boyacá | AC86: Sede Puerto Boyacá | AD86: Centro Tecnológico De La Amazonia | AE86: Centro Agroindustrial Y Fortalecimiento Empresarial De Casanare | AF86: SedeSantander De Quilichao | AG86: Sede Centro De Desarrollo VecinalCdv | AH86: Centro De Formación Centro Minero | AI86: Centro Agropecuario Y De Biotecnología El Porvenir | AJ86: SedePacho | AK86: Centro De Electricidad, Electrónica Y TelecomunicacionesComplejo Sur | AM86: Centro Industrial Y De Energías Alternativas Sede Maicao | AN86: Centro De Desarrollo Agroindustrial, Turístico Y Tecnológico Del Guaviare | AO86: Centro De Formación Agroindustrial | AP86: Sede Fundación | AQ86: Sede Los Naranjos | AR86: Centro Sur Colombiano De Logística Internacional | AS86: Regional Norte De Santander | AT86: Sibundoy | AU86: Centro Para El Desarrollo Tecnológico De La Construcción Y La Industria | AV86: Centro De Diseño E Innovación Tecnológica Industrial | AW86: Sede Bilingüismo | AX86: Sede Aguascalientes | AY86: Sede Corozal | AZ86: Sede Escuela Gastronómica | BA86: Centro Agropecuario De Buga | BB86: Regional Vaupés 2 | BC86: Sede La Primavera
U87: Regional Arauca | X87: Complejo Tecnológico, Turístico Y Agroindustrial Del Occidente Antioqueño | Y87: Unidad De Emprendimiento Y Agencia Pública De Empleo | Z87: Finca El Caney | AA87: Centro Internacional Náutico, Fluvial Y Portuario | AB87: Centro De Desarrollo Agropecuario Y Agroindustrial | AC87: Centro Pecuario Y Agroempresarial | AD87: Granja Ceilan | AF87: Centro De Comercio Y Servicios | AG87: Centro Biotecnológico Del Caribe | AH87: Centro De Recursos Naturales, Industria Y Biodiversidad | AI87: Tecnoparque Montería | AJ87: SedePuerto Salgar | AK87: Centro De Gestión IndustrialComplejo Paloquemao | AM87: Centro Agroempresarial Y Acuícola Sede Fonseca | AO87: Centro Agroempresarial Y Desarrollo Pecuario Del Huila | AP87: Centro Acuícola Y Agroindustrial De Gaira | AQ87: Sede Puerto Gaitan | AR87: Sede Muelle | AS87: Sede Pamplona | AT87: Puerto Leguizamo | AU87: Centro Agroindustrial | AV87: Tecnoacademia Dosquebradas | AW87: Campamento Providencia | AX87: Centro Industrial De Mantenimiento Integral | AY87: Centro De La Innovación La Tecnología Y Los ServiciosLa Gallera | AZ87: Centro Agropecuario La Granja | BA87: Sede Centro Náutico Pesquero De Buenaventura | BB87: Centro Agropecuario Y De Servicios Ambientales JiriJirimo | BC87: Centro De Producción Y Transformación Agroindustrial De La Orinoquía
U88: Regional Atlántico | X88: Centro Del Diseño Y Manufactura De CueroComplejo Sur | Y88: Granja El Alcaraván Arauquita | Z88: Sede Energía | AA88: Centro Para La Industria Petroquímica | AB88: Centro Minero | AC88: Tecnoacademia Manizales | AD88: Centro Tecnológico De La Amazonía | AF88: Sede Guapi | AG88: Centro Agroempresarial | AI88: San Jorge Montelíbano | AJ88: SedeSan Juan De Rio Seco | AK88: Sede Prial | AM88: Centro Agroempresarial Y Acuícola Área Administrativa | AO88: Centro De Desarrollo Agroempresarial Y Turístico Del Huila | AP88: CiénagaCentro De Logística Y Promoción Ecoturística Del Magdalena | AQ88: Sede El Taladro | AR88: Centro Agroindustrial Y Pesquero De La Costa Pacífica | AS88: Sede Centro De Calzado | AT88: Centro Agroforestal Y Acuícola Arapaima | AU88: Tecnoacademia Armenia | AV88: Santa Rosa De Cabal | AW88: Centro De Formación Turística Gente De Mar Y De Servicios | AX88: Centro Industrial Del Diseño Y La Manufactura | AY88: Sede Nueva Boston | AZ88: Escuela Postcosecha, Frutas Y Hortalizas | BA88: Centro De La Construcción | BC88: Subsede
U89: Regional Bolivar | X89: Centro Para El Desarrollo Del Hábitat Y La Construcción | Y89: Escuela De Gastronomía | Z89: Nodo Salud | AA89: Sede San Pablo | AB89: Centro De Gestión Administrativa Y Fortalecimiento Empresarial | AC89: Sede Chinchiná | AF89: Centro Integrado Para La Formación Profesional Del Norte Del Cauca – La Samaria | AG89: La Jagua De Ibirico | AI89: Centro De Comercio, Industria Y Turismo De Córdoba | AJ89: Subsede Manuel Humberto Cardenas Tulipana | AK89: Sede ÁlamosPlantas Agroindustriales | AM89: Centro Industrial Y De Energías Alternativas Área Administrativa | AO89: Centro De Gestión Y Desarrollo Sostenible Surcolombiano | AP89: Sede El Banco | AQ89: Sede Granada | AR89: Sede La Union Nariño | AS89: Tecnoparque Nodo Ocaña | AV89: Escuela Gastronómica Y Cultural "Calle De La Fundación" | AW89: Nueva Sede Providencia | AX89: Centro Industrial Y Del Desarrollo Tecnológico | AY89: Centro De La Innovación, La Tecnología Y Los Servicios | AZ89: Centro De Comercio Y Servicios | BA89: Centro De Tecnologías Agroindustriales | BC89: Subsede 2
U90: Regional Boyacá | X90: Complejo Tecnológico Para La Gestión Agroempresarial | Y90: Tecnoacademia Arauca | Z90: Nodo Construcción E Infraestructura | AA90: Sede Mompós | AB90: Sede Moniquirá | AC90: Servicio Medico Asistencial | AF90: Tecnoparque Nodo Popayán | AG90: Sede Curumani | AJ90: Centro De La Tecnología Del Diseño Y La Productividad Empresarial | AK90: Centro De Formación De Talento Humano En Salud | AO90: Tecnoparque Agroecológico Yamboró. | AP90: Regional Magdalena | AQ90: Centro De Industria Y Servicios Del Meta | AR90: Sede Ipiales | AS90: Los Patios | AV90: Centro Atención Sector Agropecuario | AX90: Centro Agroturístico | AY90: Centro de Formación Agropecuarias SENA La Mojana | BA90: Centro De Biotecnología Industrial
U91: Regional Caldas | X91: Santa Rosa De Osos | Y91: Centro De Gestión Y Desarrollo Agroindustrial De Arauca | Z91: Logística Y Transporte | AA91: Centro Agroempresarial Y Minero | AB91: Servicio Público Empleo Tunja | AC91: Centro Para La Formación Cafetera | AF91: Snft | AG91: Sede Chimichagua | AJ91: Sede Ituc | AK91: Centro De Gestión Administrativa | AO91: Tecnoparque Colombia Nodo Neiva | AP91: Sede Plato | AR91: Sede Obando | AS91: Regional Norte De SantanderBloque Formación Pescadero | AV91: Centro De Comercio Y Servicios | AX91: Sede Socorro | BA91: Centro Latinoamericano De Especies Menores
U92: Regional Caquetá | X92: Complejo Tecnológico Minero Agroempresarial | Z92: Sede Centro Nacional Colombo AlemánMalambo | AA92: Centro De Comercio Y Servicios | AB92: Escuela Gastronómica De Tunja | AC92: Centro De Automatización Industrial | AF92: Archivo Central | AG92: Sede San Alberto | AJ92: Centro De Biotecnología Agropecuaria | AK92: Centro de formación en actividad física y culturaOnassis | AO92: Tecnoacademia Neiva | AP92: Bodega | AR92: Tecnoacademia Del Centro Surcolombiano De Logística Internacional | AS92: Sede Confecciones Y MaderaComuneros | AX92: Centro Agroempresarial Y Turístico De Los Andes | BA92: Spe Tuluá
...

Sheet Instrucciones (2)
I1: Versión: 06
I2: Código: GTI-F-029
A3: PROCESO | J3: Versión: 05
A4: Gestión de Tecnologías de la Información
A5: NOMBRE DEL FORMATO
A6: Formato de Petición de Accesos Directorio Activo y Correo Electrónico
A7: CLASIFICACIÓN DE LA INFORMACIÓN
A8: Pública | C8: Pública Clasificada | F8: Pública Reservada
A9: INSTRUCCIONES PARA EL DILIGENCIAMIENTO DEL FORMATO
A10: NO IMPRIMIR
A11: 1. Generalidades
A12: a) Objetivo del formato: Crear cuentas de correo electrónico y usuario de directorio activo
A13: b) ¿Si hay un procedimiento que refiera este formato?: GTI-GO-016 Guía operacional Gestión de Accesos
A14: c) ¿Quién(es) lo diligencian?:Líderes TIC y funcionarios SENA
A15: d) Frecuencia de diligenciamiento: Por demanda
A16: e) Qué trámite surte el formato una vez diligenciado: Se envía a la Mesa de Servicios
A17: f) Si se requiere imprimir: No
A18: g) Quién lo guarda: Se adjunta al caso en la herramienta de gestión
A19: 2. Instrucciones para diligenciar las casillas
A21: NOMBRE DE LA CASILLA | B21: INSTRUCCIONES | F21: TENER EN CUENTA
A22: Datos del Autorizador
A23: Nombres | B23: Diligencie los nombres del autorizador
A24: Apellidos | B24: Diligencie los apellidos del autorizador
A25: Correo electrónico | B25: Diligencie el correo electrónico
A26: Regional | B26: Diligencie los datos de la regional
A27: Ubicación | B27: Diligencie la ubicación del autorizador
A28: Solicitud de Cuentas de Red y Correo
A29: No. | B29: Número consecutivo de 1 a N.
A30: Tipo de solicitud | B30: Seleccione el tipo de solicitud: - Crear: El funcionario es nuevo - Modificar: La cuenta existe y se va a modificar algún parámetro - Activar: La cuenta existe pero se encuentra caducada - Inactivar: Se requiere inactivar alguna cuenta existente | F30: Campo obligatorio
A31: Correo electrónico Institucional | B31: Diligencie el correo electrónico institucional. Solo para modificar, activar o eliminar. | F31: En caso de que el tipo de solicitud sea "Crear", por favor no diligenciar o dejar en blanco esta celda. En caso de ser cuenta genérica coloque el nombre propuesto para la cuenta genérica. El nombre propuesto debe contener menos de 20 caracteres antes del @sena.edu.co
A32: Nombres | B32: Diligencie los nombres del funcionario. | F32: En caso de ser cuenta genérica diligencie los nombres del responsable. Campo obligatorio
A33: Apellidos | B33: Diligencie los apellidos del funcionario. | F33: En caso de ser cuenta genérica diligencie los apellidos del responsable. Campo obligatorio
A34: Documento de Identidad | B34: Diligencie el documento de identidad. | F34: Campo obligatorio
A35: Número Celular | B35: Diligencie el número celular | F35: Campo obligatorio
A36: Correo Personal | B36: Diligencie el correo electrónico personal | F36: Campo obligatorio
A37: Tipo de vinculación | B37: Seleccione de la lista desplegable | F37: Campo obligatorio
A38: Cargo | B38: Seleccione de la lista desplegable | F38: Si su tipo de vinculación pertenece a Contratista por políticas del SENA su Rol / Cargo es Contratista. Campo obligatorio
A39: Rol | B39: Seleccione de la lista desplegable | F39: Seleccione su rol dentro de la entidad
A40: ID sede | B40: Relacione el id sede a la cual pertenece | F40: No modificar
A41: Regional | B41: Relacione la regional de la sede a la cual pertenece | F41: No modificar
...

Sheet Formato
S1: Versión: 06
S5: Código: GTI-F-029
A9: PROCESO
A10: Gestión de Tecnologías de la Información
A11: NOMBRE DEL FORMATO
A12: Formato de Petición de Accesos Directorio Activo y Correo Electrónico
A13: CLASIFICACIÓN DE LA INFORMACIÓN
A14: Pública | G14: Pública Clasificada | K14: Pública Reservada
A16: 1. Datos del autorizador
A17: Nombres | E17: Apellidos | I17: Correo electrónico del autorizador (@sena.edu.co) | P17: Ubicación
A18: CAROLINA | E18: HERNANDEZ VARGAS | I18: cahernandezv@sena.edu.co
A19: 2. Solicitud de Cuentas de Red y Correo
A20: No. | B20: Tipo De Solicitud | C20: Correo electrónico institucional (@sena.edu.co) | D20: Nombres | E20: Apellidos | F20: Documento de identidad | G20: Número celular | H20: Correo personal | I20: Tipo de vinculación | J20: Cargo | K20: Rol | L20: Nombre sede | M20: Dirección sede | N20: ID sede | O20: Regional | P20: Número EXT (IP) | Q20: Fecha de terminación de contrato (dd/mm/yy) | R20: VPN | S20: Observaciones/Descripción
A21: 2 | B21: Crear | D21: ELIZABETH | E21: MUÑOZ PEÑUELA | F21: 52071152 | G21: 3105508283 | H21: elizabethmuno30@gmail.com | I21: Planta | J21: Profesional G03 | K21: Administrativo | L21: Bogotá Centro De Materiales Y Ensayos | M21: Avenida 30 No 17B-25 Sur | N21: 24C | O21: Distrito Capital
A22: 3
A23: 4
A24: 5
A25: 6
A26: 7
A27: 8
A28: 9
A29: 10
A30: 11
A31: 12
A32: 13
A33: 14
... A59: 40
A60: 3. Solicitud de Cuentas de Correo Genéricas | J60: Justificación de la Solicitud para Cuentas de correo genéricas
A61: No. | B61: Tipo de Solicitud | C61: Nombre propuesto | D61: Responsable | F61: Correo Institucional del responsable
A62: 1
A63: 2
A64: 3
A65: 4
A66: 5
A67: RESPONSABILIDADES: Este documento debe estar debidamente diligenciado y deberá ser enviado a la MESA DE SERVICIO (mesadeservicio@sena.edu.co), teniendo la aprobación del Usuario Autorizador. Favor tener en cuenta las siguientes observaciones: • El usuario tendrá 16 horas hábiles para notificar al Usuario Autorizador o a la Mesa de servicio la funcionalidad de los accesos otorgados por correo electrónico, pasado este tiempo se dará por aceptado y cerrado. • La custodia de las solicitudes reposará en la MESA DE SERVICIO. • Todos los campos del formato deben diligenciarse de acuerdo con el tipo de solicitud (Cuenta de red y correo o Cuentas de correo genéricas) en su totalidad a menos que el campo indique lo contrario.
